{"name": "test_check_wrong", "status": "skipped", "statusDetails": {"message": "XFAIL\n\nAssertionError: assert 5 == 6", "trace": "@pytest.mark.xfail\n    def test_check_wrong():\n        c = 5\n        print('Hello world' * c)\n>       assert c == 6\nE       assert 5 == 6\n\ntests\\test_check.py:14: AssertionError"}, "attachments": [{"name": "stdout", "source": "d37a0fdf-6b94-4cd7-9596-162b03eebb2f-attachment.txt", "type": "text/plain"}], "start": 1675839117151, "stop": 1675839117153, "uuid": "903264ba-8385-4041-9117-7f7bece33657", "historyId": "093a86e7b86cb0026ebca269603de16b", "testCaseId": "38af49b3590a539f2303aff5ce763360", "fullName": "tests.test_check#test_check_wrong", "labels": [{"name": "tag", "value": "@pytest.mark.xfail"}, {"name": "parentSuite", "value": "tests"}, {"name": "suite", "value": "test_check"}, {"name": "host", "value": "DESKTOP-O0EVL3P"}, {"name": "thread", "value": "14632-MainThread"}, {"name": "framework", "value": "pytest"}, {"name": "language", "value": "cpython3"}, {"name": "package", "value": "tests.test_check"}]}